Workbook

Sheet Calculadora
A1: CALCULADORA INTELIGENTE DE COSTE DE VIVIENDA
A3: DATOS DE LA VIVIENDA
A4: M² construidos | B4: 100
A5: Número de plantas | B5: 2
A6: Habitaciones | B6: 2
A7: Baños | B7: 2
A8: Calidad (Básica/Media/Alta) | B8: Media
A9: Climatización (Convencional/Aerotermia/Aerotermia + suelo radiante) | B9: Aerotermia + suelo radiante
A10: Domótica (Sí/No) | B10: No
A11: Piscina (Sin piscina/Pequeña/Mediana/Grande) | B11: Mediana
A12: Plazas aparcamiento exterior | B12: 0
A13: M² exterior/jardín | B13: 0
A14: Proyecto/licencias (Sí/No) | B14: No
A17: RESUMEN POR PARTIDAS
A18: Partida | B18: Base cálculo | C18: Precio | D18: Total
A19: Excavación | B19: =$B$4 | C19: =INDEX(Precios!$B$4:$D$26,MATCH("Excavación €/m²",Precios!$A$4:$A$26,0),MATCH($B$8,{"Básica","Media","Alta"},0)) | D19: =B19*C19
A20: Estructura | B20: =$B$4 | C20: =INDEX(Precios!$B$4:$D$26,MATCH("Estructura €/m²",Precios!$A$4:$A$26,0),MATCH($B$8,{"Básica","Media","Alta"},0)) | D20: =B20*C20
A21: Cubierta | B21: =($B$4/$B$5)*1.3 | C21: =INDEX(Precios!$B$4:$D$26,MATCH("Cubierta €/m²",Precios!$A$4:$A$26,0),MATCH($B$8,{"Básica","Media","Alta"},0)) | D21: =B21*C21
A22: Fachada | B22: =4*SQRT($B$4/$B$5)*3*$B$5 | C22: =INDEX(Precios!$B$4:$D$26,MATCH("Fachada €/m²",Precios!$A$4:$A$26,0),MATCH($B$8,{"Básica","Media","Alta"},0)) | D22: =B22*C22
A23: Tabiquería | B23: =$B$4*2.5 | C23: =INDEX(Precios!$B$4:$D$26,MATCH("Tabiquería €/m²",Precios!$A$4:$A$26,0),MATCH($B$8,{"Básica","Media","Alta"},0)) | D23: =B23*C23
A24: Acabados paredes | B24: =$B$4*2.5 | C24: =INDEX(Precios!$B$4:$D$26,MATCH("Acabados paredes €/m²",Precios!$A$4:$A$26,0),MATCH($B$8,{"Básica","Media","Alta"},0)) | D24: =B24*C24
A25: Suelos | B25: =$B$4 | C25: =INDEX(Precios!$B$4:$D$26,MATCH("Suelos €/m²",Precios!$A$4:$A$26,0),MATCH($B$8,{"Básica","Media","Alta"},0)) | D25: =B25*C25
A26: Electricidad | B26: =$B$4 | C26: =INDEX(Precios!$B$4:$D$26,MATCH("Electricidad €/m²",Precios!$A$4:$A$26,0),MATCH($B$8,{"Básica","Media","Alta"},0)) | D26: =B26*C26
A27: Fontanería | B27: =$B$4 | C27: =INDEX(Precios!$B$4:$D$26,MATCH("Fontanería €/m²",Precios!$A$4:$A$26,0),MATCH($B$8,{"Básica","Media","Alta"},0)) | D27: =B27*C27
A28: Ventanas + persianas | B28: =($B$6+$B$7+2)*1.4 | C28: =INDEX(Precios!$B$4:$D$26,MATCH("Ventana base €/ud",Precios!$A$4:$A$26,0),MATCH($B$8,{"Básica","Media","Alta"},0)) | D28: =B28*C28
A29: Cristalera salón | B29: =1 | C29: =INDEX(Precios!$B$4:$D$26,MATCH("Cristalera salón €/ud",Precios!$A$4:$A$26,0),MATCH($B$8,{"Básica","Media","Alta"},0)) | D29: =B29*C29
A30: Puertas interiores | B30: =$B$6+$B$7+3 | C30: =INDEX(Precios!$B$4:$D$26,MATCH("Puerta interior €/ud",Precios!$A$4:$A$26,0),MATCH($B$8,{"Básica","Media","Alta"},0)) | D30: =B30*C30
A31: Puerta principal | B31: =1 | C31: =INDEX(Precios!$B$4:$D$26,MATCH("Puerta principal €/ud",Precios!$A$4:$A$26,0),MATCH($B$8,{"Básica","Media","Alta"},0)) | D31: =B31*C31
A32: Baños | B32: =$B$7 | C32: =INDEX(Precios!$B$4:$D$26,MATCH("Baño €/ud",Precios!$A$4:$A$26,0),MATCH($B$8,{"Básica","Media","Alta"},0)) | D32: =B32*C32
A33: Cocina | B33: =1 | C33: =INDEX(Precios!$B$4:$D$26,MATCH("Cocina €/ud",Precios!$A$4:$A$26,0),MATCH($B$8,{"Básica","Media","Alta"},0)) | D33: =B33*C33
A34: Climatización | B34: =$B$4 | C34: =IF($B$9="Convencional",=INDEX(Precios!$B$4:$D$26,MATCH("Climatización convencional €/m²",Precios!$A$4:$A$26,0),MATCH($B$8,{"Básica","Media","Alta"},0)),IF($B$9="Aerotermia",=INDEX(Precios!$B$4:$D$26,MATCH("Aerotermia €/m²",Precios!$A$4:$A$26,0),MATCH($B$8,{"Básica","Media","Alta"},0)),=INDEX(Precios!$B$4:$D$26,MATCH("Aerotermia + suelo radiante €/m²",Precios!$A$4:$A$26,0),MATCH($B$8,{"Básica","Media","Alta"},0)))) | D34: =B34*C34
A35: Domótica | B35: =IF($B$10="Sí",1,0) | C35: =INDEX(Precios!$B$4:$D$26,MATCH("Domótica €/ud",Precios!$A$4:$A$26,0),MATCH($B$8,{"Básica","Media","Alta"},0)) | D35: =B35*C35
A36: Piscina | B36: =IF($B$11="Pequeña",6,IF($B$11="Mediana",12,IF($B$11="Grande",20,0))) | C36: =INDEX(Precios!$B$4:$D$26,MATCH("Piscina €/m² lámina",Precios!$A$4:$A$26,0),MATCH($B$8,{"Básica","Media","Alta"},0)) | D36: =B36*C36
A37: Jardín/exterior | B37: =$B$13 | C37: =INDEX(Precios!$B$4:$D$26,MATCH("Jardín/exterior €/m²",Precios!$A$4:$A$26,0),MATCH($B$8,{"Básica","Media","Alta"},0)) | D37: =B37*C37
A38: Aparcamiento exterior | B38: =$B$12 | C38: =INDEX(Precios!$B$4:$D$26,MATCH("Aparcamiento exterior €/plaza",Precios!$A$4:$A$26,0),MATCH($B$8,{"Básica","Media","Alta"},0)) | D38: =B38*C38
A39: Escaleras | B39: =MAX($B$5-1,0) | C39: =INDEX(Precios!$B$4:$D$26,MATCH("Escalera €/tramo",Precios!$A$4:$A$26,0),MATCH($B$8,{"Básica","Media","Alta"},0)) | D39: =B39*C39
A40: COSTE BASE | D40: =SUM(D19:D39)
A41: IMPREVISTOS (5%) | D41: =D40*5%
A42: BENEFICIO (30% tras imprevistos) | D42: =(D40+D41)*30%
A43: TOTAL CONSTRUCCIÓN | D43: =D40+D41+D42
...

Sheet Precios
A1: PRECIOS BASE REAJUSTADOS
A3: Partida | B3: Básica | C3: Media | D3: Alta
A4: Excavación €/m² | B4: 75.9625 | C4: 72.924 | D4: 69.8855
A5: Estructura €/m² | B5: 625 | C5: 720 | D5: 862.5
A6: Cubierta €/m² | B6: 100 | C6: 120 | D6: 149.5
A7: Fachada €/m² | B7: 150 | C7: 180 | D7: 230
A8: Tabiquería €/m² | B8: 56.25 | C8: 84 | D8: 103.5
A9: Acabados paredes €/m² | B9: 87.5 | C9: 144 | D9: 195.5
A10: Suelos €/m² | B10: 125 | C10: 144 | D10: 184
A11: Electricidad €/m² | B11: 93.75 | C11: 108 | D11: 138
A12: Fontanería €/m² | B12: 87.5 | C12: 108 | D12: 138
A13: Ventana base €/ud | B13: 437.5 | C13: 480 | D13: 517.5
A14: Cristalera salón €/ud | B14: 7500 | C14: 9600 | D14: 13800
A15: Puerta interior €/ud | B15: 312.5 | C15: 480 | D15: 805
... A26: Escalera €/tramo | B26: 5000 | C26: 7200 | D26: 10350

Sheet Notas
A1: NOTAS IMPORTANTES
A3: Los precios se han reajustado: Básica +25%, Media +20%, Alta +15%.
A4: Las partidas marcadas como provisionales se pueden editar directamente en la hoja Precios cuando recuperes los valores históricos exactos.
A5: Garaje incluido dentro de los 100 m²: no se añade como aparcamiento exterior.
A6: El total aplica siempre: Coste base +5% imprevistos y después +30% beneficio.
